{
 "cells": [
  {
   "cell_type": "code",
   "execution_count": 7,
   "id": "411a803a",
   "metadata": {},
   "outputs": [],
   "source": [
    "from PIL import Image"
   ]
  },
  {
   "cell_type": "code",
   "execution_count": null,
   "id": "aaacfdc9",
   "metadata": {},
   "outputs": [],
   "source": [
    "blue = Image.open('blue.png')"
   ]
  },
  {
   "cell_type": "code",
   "execution_count": 9,
   "id": "e5c559b6",
   "metadata": {},
   "outputs": [
    {
     "ename": "ValueError",
     "evalue": "Could not save to PNG for display",
     "output_type": "error",
     "traceback": [
      "\u001B[0;31m---------------------------------------------------------------------------\u001B[0m",
      "\u001B[0;31mKeyError\u001B[0m                                  Traceback (most recent call last)",
      "\u001B[0;32m/usr/lib/python3/dist-packages/PIL/PngImagePlugin.py\u001B[0m in \u001B[0;36m_save\u001B[0;34m(im, fp, filename, chunk, save_all)\u001B[0m\n\u001B[1;32m   1228\u001B[0m     \u001B[0;32mtry\u001B[0m\u001B[0;34m:\u001B[0m\u001B[0;34m\u001B[0m\u001B[0;34m\u001B[0m\u001B[0m\n\u001B[0;32m-> 1229\u001B[0;31m         \u001B[0mrawmode\u001B[0m\u001B[0;34m,\u001B[0m \u001B[0mmode\u001B[0m \u001B[0;34m=\u001B[0m \u001B[0m_OUTMODES\u001B[0m\u001B[0;34m[\u001B[0m\u001B[0mmode\u001B[0m\u001B[0;34m]\u001B[0m\u001B[0;34m\u001B[0m\u001B[0;34m\u001B[0m\u001B[0m\n\u001B[0m\u001B[1;32m   1230\u001B[0m     \u001B[0;32mexcept\u001B[0m \u001B[0mKeyError\u001B[0m \u001B[0;32mas\u001B[0m \u001B[0me\u001B[0m\u001B[0;34m:\u001B[0m\u001B[0;34m\u001B[0m\u001B[0;34m\u001B[0m\u001B[0m\n",
      "\u001B[0;31mKeyError\u001B[0m: 'PA'",
      "\nThe above exception was the direct cause of the following exception:\n",
      "\u001B[0;31mOSError\u001B[0m                                   Traceback (most recent call last)",
      "\u001B[0;32m/usr/lib/python3/dist-packages/PIL/Image.py\u001B[0m in \u001B[0;36m_repr_png_\u001B[0;34m(self)\u001B[0m\n\u001B[1;32m    651\u001B[0m         \u001B[0;32mtry\u001B[0m\u001B[0;34m:\u001B[0m\u001B[0;34m\u001B[0m\u001B[0;34m\u001B[0m\u001B[0m\n\u001B[0;32m--> 652\u001B[0;31m             \u001B[0mself\u001B[0m\u001B[0;34m.\u001B[0m\u001B[0msave\u001B[0m\u001B[0;34m(\u001B[0m\u001B[0mb\u001B[0m\u001B[0;34m,\u001B[0m \u001B[0;34m\"PNG\"\u001B[0m\u001B[0;34m)\u001B[0m\u001B[0;34m\u001B[0m\u001B[0;34m\u001B[0m\u001B[0m\n\u001B[0m\u001B[1;32m    653\u001B[0m         \u001B[0;32mexcept\u001B[0m \u001B[0mException\u001B[0m \u001B[0;32mas\u001B[0m \u001B[0me\u001B[0m\u001B[0;34m:\u001B[0m\u001B[0;34m\u001B[0m\u001B[0;34m\u001B[0m\u001B[0m\n",
      "\u001B[0;32m/usr/lib/python3/dist-packages/PIL/Image.py\u001B[0m in \u001B[0;36msave\u001B[0;34m(self, fp, format, **params)\u001B[0m\n\u001B[1;32m   2211\u001B[0m         \u001B[0;32mtry\u001B[0m\u001B[0;34m:\u001B[0m\u001B[0;34m\u001B[0m\u001B[0;34m\u001B[0m\u001B[0m\n\u001B[0;32m-> 2212\u001B[0;31m             \u001B[0msave_handler\u001B[0m\u001B[0;34m(\u001B[0m\u001B[0mself\u001B[0m\u001B[0;34m,\u001B[0m \u001B[0mfp\u001B[0m\u001B[0;34m,\u001B[0m \u001B[0mfilename\u001B[0m\u001B[0;34m)\u001B[0m\u001B[0;34m\u001B[0m\u001B[0;34m\u001B[0m\u001B[0m\n\u001B[0m\u001B[1;32m   2213\u001B[0m         \u001B[0;32mfinally\u001B[0m\u001B[0;34m:\u001B[0m\u001B[0;34m\u001B[0m\u001B[0;34m\u001B[0m\u001B[0m\n",
      "\u001B[0;32m/usr/lib/python3/dist-packages/PIL/PngImagePlugin.py\u001B[0m in \u001B[0;36m_save\u001B[0;34m(im, fp, filename, chunk, save_all)\u001B[0m\n\u001B[1;32m   1230\u001B[0m     \u001B[0;32mexcept\u001B[0m \u001B[0mKeyError\u001B[0m \u001B[0;32mas\u001B[0m \u001B[0me\u001B[0m\u001B[0;34m:\u001B[0m\u001B[0;34m\u001B[0m\u001B[0;34m\u001B[0m\u001B[0m\n\u001B[0;32m-> 1231\u001B[0;31m         \u001B[0;32mraise\u001B[0m \u001B[0mOSError\u001B[0m\u001B[0;34m(\u001B[0m\u001B[0;34mf\"cannot write mode {mode} as PNG\"\u001B[0m\u001B[0;34m)\u001B[0m \u001B[0;32mfrom\u001B[0m \u001B[0me\u001B[0m\u001B[0;34m\u001B[0m\u001B[0;34m\u001B[0m\u001B[0m\n\u001B[0m\u001B[1;32m   1232\u001B[0m \u001B[0;34m\u001B[0m\u001B[0m\n",
      "\u001B[0;31mOSError\u001B[0m: cannot write mode PA as PNG",
      "\nThe above exception was the direct cause of the following exception:\n",
      "\u001B[0;31mValueError\u001B[0m                                Traceback (most recent call last)",
      "\u001B[0;32m/usr/lib/python3/dist-packages/IPython/core/formatters.py\u001B[0m in \u001B[0;36m__call__\u001B[0;34m(self, obj)\u001B[0m\n\u001B[1;32m    343\u001B[0m             \u001B[0mmethod\u001B[0m \u001B[0;34m=\u001B[0m \u001B[0mget_real_method\u001B[0m\u001B[0;34m(\u001B[0m\u001B[0mobj\u001B[0m\u001B[0;34m,\u001B[0m \u001B[0mself\u001B[0m\u001B[0;34m.\u001B[0m\u001B[0mprint_method\u001B[0m\u001B[0;34m)\u001B[0m\u001B[0;34m\u001B[0m\u001B[0;34m\u001B[0m\u001B[0m\n\u001B[1;32m    344\u001B[0m             \u001B[0;32mif\u001B[0m \u001B[0mmethod\u001B[0m \u001B[0;32mis\u001B[0m \u001B[0;32mnot\u001B[0m \u001B[0;32mNone\u001B[0m\u001B[0;34m:\u001B[0m\u001B[0;34m\u001B[0m\u001B[0;34m\u001B[0m\u001B[0m\n\u001B[0;32m--> 345\u001B[0;31m                 \u001B[0;32mreturn\u001B[0m \u001B[0mmethod\u001B[0m\u001B[0;34m(\u001B[0m\u001B[0;34m)\u001B[0m\u001B[0;34m\u001B[0m\u001B[0;34m\u001B[0m\u001B[0m\n\u001B[0m\u001B[1;32m    346\u001B[0m             \u001B[0;32mreturn\u001B[0m \u001B[0;32mNone\u001B[0m\u001B[0;34m\u001B[0m\u001B[0;34m\u001B[0m\u001B[0m\n\u001B[1;32m    347\u001B[0m         \u001B[0;32melse\u001B[0m\u001B[0;34m:\u001B[0m\u001B[0;34m\u001B[0m\u001B[0;34m\u001B[0m\u001B[0m\n",
      "\u001B[0;32m/usr/lib/python3/dist-packages/PIL/Image.py\u001B[0m in \u001B[0;36m_repr_png_\u001B[0;34m(self)\u001B[0m\n\u001B[1;32m    652\u001B[0m             \u001B[0mself\u001B[0m\u001B[0;34m.\u001B[0m\u001B[0msave\u001B[0m\u001B[0;34m(\u001B[0m\u001B[0mb\u001B[0m\u001B[0;34m,\u001B[0m \u001B[0;34m\"PNG\"\u001B[0m\u001B[0;34m)\u001B[0m\u001B[0;34m\u001B[0m\u001B[0;34m\u001B[0m\u001B[0m\n\u001B[1;32m    653\u001B[0m         \u001B[0;32mexcept\u001B[0m \u001B[0mException\u001B[0m \u001B[0;32mas\u001B[0m \u001B[0me\u001B[0m\u001B[0;34m:\u001B[0m\u001B[0;34m\u001B[0m\u001B[0;34m\u001B[0m\u001B[0m\n\u001B[0;32m--> 654\u001B[0;31m             \u001B[0;32mraise\u001B[0m \u001B[0mValueError\u001B[0m\u001B[0;34m(\u001B[0m\u001B[0;34m\"Could not save to PNG for display\"\u001B[0m\u001B[0;34m)\u001B[0m \u001B[0;32mfrom\u001B[0m \u001B[0me\u001B[0m\u001B[0;34m\u001B[0m\u001B[0;34m\u001B[0m\u001B[0m\n\u001B[0m\u001B[1;32m    655\u001B[0m         \u001B[0;32mreturn\u001B[0m \u001B[0mb\u001B[0m\u001B[0;34m.\u001B[0m\u001B[0mgetvalue\u001B[0m\u001B[0;34m(\u001B[0m\u001B[0;34m)\u001B[0m\u001B[0;34m\u001B[0m\u001B[0;34m\u001B[0m\u001B[0m\n\u001B[1;32m    656\u001B[0m \u001B[0;34m\u001B[0m\u001B[0m\n",
      "\u001B[0;31mValueError\u001B[0m: Could not save to PNG for display"
     ]
    },
    {
     "data": {
      "text/plain": [
       "<PIL.PngImagePlugin.PngImageFile image mode=PA size=800x800 at 0x7F9D79E3FA90>"
      ]
     },
     "execution_count": 9,
     "metadata": {},
     "output_type": "execute_result"
    }
   ],
   "source": [
    "blue"
   ]
  },
  {
   "cell_type": "code",
   "execution_count": null,
   "id": "1aa2497f",
   "metadata": {},
   "outputs": [],
   "source": []
  }
 ],
 "metadata": {
  "kernelspec": {
   "display_name": "Python 3 (ipykernel)",
   "language": "python",
   "name": "python3"
  },
  "language_info": {
   "codemirror_mode": {
    "name": "ipython",
    "version": 3
   },
   "file_extension": ".py",
   "mimetype": "text/x-python",
   "name": "python",
   "nbconvert_exporter": "python",
   "pygments_lexer": "ipython3",
   "version": "3.10.6"
  }
 },
 "nbformat": 4,
 "nbformat_minor": 5
}
